Workbook

Sheet Configuración
A1: CONFIGURACIÓN PERSONAL
A3: ¿Tiene cónyuge a cargo? | B3: NO
A4: Cantidad de hijos | B4: 0
A5: Hijos incapacitados | B5: 0
A7: Tipo de Deducción Especial: | B7: General / Profesionales / Corredores-Viajantes / Personal Antártida
A8: Seleccione: | B8: General

Sheet Parametros
A1: DEDUCCIONES PERSONALES - Enero a Junio 2025 | D1: DEDUCCIONES PERSONALES - Julio a Diciembre 2025
A3: Ganancia No Imponible (MNI) | B3: 326355.7 | D3: Ganancia No Imponible (MNI) | E3: 326355.7
A4: Deducción por Cónyuge | B4: 302130.08 | D4: Deducción por Cónyuge | E4: 302130.08
A5: Deducción por Hijo | B5: 159273.44 | D5: Deducción por Hijo | E5: 159273.44
A6: Deducción por Hijo Incapacitado | B6: 318546.87 | D6: Deducción por Hijo Incapacitado | E6: 318546.87
A8: Deducción Especial - General | B8: 1142244.9 | D8: Deducción Especial - General | E8: 1142244.9
A9: Deducción Especial - Profesionales Nuevos | B9: 1713367.4 | D9: Deducción Especial - Profesionales Nuevos | E9: 1713367.4
A10: Deducción Especial - Zona Desfavorable | B10: 1827832.9 | D10: Deducción Especial - Zona Desfavorable (NO VIGENTE 2025) | E10: 0
A13: ESCALAS PROGRESIVAS - ENERO A JUNIO 2025 (Tabla Oficial ARCA)
A14: Ganancia Neta Acumulada | B14: Hasta | C14: Pagarán | D14: Más el % | E14: Sobre excedente de
A15: 0 | B15: 126697.64 | C15: 0 | D15: 0.05 | E15: 0
A16: 126697.64 | B16: 253395.28 | C16: 6334.88 | D16: 0.09 | E16: 126697.64
A17: 253395.28 | B17: 380092.92 | C17: 17737.67 | D17: 0.12 | E17: 253395.28
A18: 380092.92 | B18: 570139.38 | C18: 32941.39 | D18: 0.15 | E18: 380092.92
A19: 570139.38 | B19: 1140278.8 | C19: 61448.36 | D19: 0.19 | E19: 570139.38
A20: 1140278.8 | B20: 1710418.1 | C20: 169774.84 | D20: 0.23 | E20: 1140278.8
A21: 1710418.1 | B21: 2565627.2 | C21: 300906.89 | D21: 0.27 | E21: 1710418.1
A22: 2565627.2 | B22: 3848440.8 | C22: 531813.34 | D22: 0.31 | E22: 2565627.2
A23: 3848440.8 | C23: 929485.56 | D23: 0.35 | E23: 3848440.8
A25: ESCALAS PROGRESIVAS - Julio a Diciembre 2025
A26: ESCALAS PROGRESIVAS - JULIO A DICIEMBRE 2025 (Tabla Oficial ARCA) | B26: Hasta | C26: Pagarás | D26: Más el % | E26: Sobre excedente de
A27: Ganancia Neta Acumulada | B27: Hasta | C27: Pagarán | D27: Más el % | E27: Sobre excedente de
A28: 0 | B28: 886883.47 | C28: 0 | D28: 0.05 | E28: 0
A29: 886883.47 | B29: 1773766.9 | C29: 44344.17 | D29: 0.09 | E29: 886883.47
A30: 1773766.9 | B30: 2660650.4 | C30: 124163.69 | D30: 0.12 | E30: 1773766.9
A31: 2660650.4 | B31: 3990975.6 | C31: 230589.7 | D31: 0.15 | E31: 2660650.4
A32: 3990975.6 | B32: 7981951.3 | C32: 430138.49 | D32: 0.19 | E32: 3990975.6
A33: 7981951.3 | B33: 11972927 | C33: 1188423.9 | D33: 0.23 | E33: 7981951.3
A34: 11972927 | B34: 17959390 | C34: 2106348.2 | D34: 0.27 | E34: 11972927
A35: 17959390 | B35: 26939086 | C35: 3722693.4 | D35: 0.31 | E35: 17959390
A36: 26939086 | C36: 6506398.9 | D36: 0.35 | E36: 26939086
A38: TOPES MoPre MENSUALES 2025 | D38: DEDUCCIONES GENERALES - TOPES | G38: Tope de la deducción: 5% de la ganancia neta del ejercicio acumulada hasta el mes que se liquida (item 6, Ganancia neta del mes que se liquida...) antes de restar de la misma, si los hubiera, los siguientes importes deducibles:
A39: Mes | B39: Tope MoPre | D39: Concepto | E39: Tope | G39: Tope5% | H39: a) donaciones permitidas (ver detalle en anexo) | I39: b) honorarios pagados por servicios de asistencia sanitaria, médica y paramédica del contribuyente y de las personas que revistan para éste el carácter de cargas de familia (ver detalle en anexo) | J39: c) quebrantos de años anteriores | K39: d) ganancia mínima no imponible (monto a deducir fijo y actualizable automáticamente por semestres según IPC acumulada del semestre) | L39: e) deducción especial (ver detalles en anexo) | M39: f) deducción especial doceava parte | N39: g) cargas de familia (ver detalle en anexo) | O39: descuentos obligatorios efectuados para aportes para obras sociales correspondientes al contribuyente y a las personas que revistan para éste el carácter de cargas de familia | P39: Importes que se destinen a cuotas o abonos a instituciones que presten cobertura médico asistencial (ej. Medicina prepaga), correspondientes al beneficiario y a las personas que revistan para el mismo el carácter de cargas de familia
A40: Enero | B40: 2910574 | D40: Medicina Prepaga | E40: 5% de GNSI | G40: Medicina prepaga
A41: Febrero | B41: 2910574 | D41: Seguro de Vida | E41: 5% de GNSI | F41: TOPE FIJO SEMESTRAL ARCA (no 5%)
A42: Marzo | B42: 2910574 | D42: Donaciones | E42: 5% de GNSI | G42: Donaciones
A43: Abril | B43: 2910574 | D43: Alquiler 40% | E43: Hasta MNI
A44: Mayo | B44: 2910574 | D44: Empleada Doméstica | E44: Hasta MNI
A45: Junio | B45: 2910574 | D45: Honorarios por servicios de asistencia médica, paramédica y sanitaria | F45: 40% por factura + Tope 5% GNSI total | G45: Honorarios por servicios de asistencia médica, paramédica y sanitaria
A46: Julio | B46: 2910574
...

Sheet Liquidación Anual 2025
A1: CONCEPTO | B1: Ene | C1: Feb | D1: Mar | E1: Abr | F1: May | G1: Jun | H1: Jul | I1: Ago | J1: Sep | K1: Oct | L1: Nov | M1: Dic
A2: LIQUIDACIÓN ANUAL 2025 - IMPUESTO A LAS GANANCIAS (4ta CATEGORÍA)
A3: 1. INGRESOS DEL MES
A4: Sueldo Básico | B4: 5927497 | C4: 0 | D4: 0 | E4: 0 | F4: 0 | G4: 0 | H4: 0 | I4: 0 | J4: 0 | K4: 0 | L4: 0 | M4: 0
A5: Adicionales Habituales | B5: 0 | C5: 0 | D5: 0 | E5: 0 | F5: 0 | G5: 0 | H5: 0 | I5: 0 | J5: 0 | K5: 0 | L5: 0 | M5: 0
A6: Antigüedad | B6: 0 | C6: 0 | D6: 0 | E6: 0 | F6: 0 | G6: 0 | H6: 0 | I6: 0 | J6: 0 | K6: 0 | L6: 0 | M6: 0
A7: Comisiones | B7: 0 | C7: 0 | D7: 0 | E7: 0 | F7: 0 | G7: 0 | H7: 0 | I7: 0 | J7: 0 | K7: 0 | L7: 0 | M7: 0
A8: Plus Vacacional | B8: 0 | C8: 0 | D8: 0 | E8: 0 | F8: 0 | G8: 0 | H8: 0 | I8: 0 | J8: 0 | K8: 0 | L8: 0 | M8: 0
A9: Otros Conceptos Remunerativos | B9: 0 | C9: 0 | D9: 0 | E9: 0 | F9: 0 | G9: 0 | H9: 0 | I9: 0 | J9: 0 | K9: 0 | L9: 0 | M9: 0
A10: Conceptos No Remunerativos Habituales | B10: 0 | C10: 0 | D10: 0 | E10: 0 | F10: 0 | G10: 0 | H10: 0 | I10: 0 | J10: 0 | K10: 0 | L10: 0 | M10: 0
A11: Conceptos No Remunerativos No Habituales | B11: 0 | C11: 0 | D11: 0 | E11: 0 | F11: 0 | G11: 0 | H11: 0 | I11: 0 | J11: 0 | K11: 0 | L11: 0 | M11: 0
A12: SAC / Aguinaldo | B12: 0 | C12: 0 | D12: 0 | E12: 0 | F12: 0 | G12: 0 | H12: 0 | I12: 0 | J12: 0 | K12: 0 | L12: 0 | M12: 0
A13: Total Ingresos del Mes | B13: =B4+B5+B6+B7+B8+B9+B10+B11+B12 | C13: =C4+C5+C6+C7+C8+C9+C10+C11+C12 | D13: =D4+D5+D6+D7+D8+D9+D10+D11+D12 | E13: =E4+E5+E6+E7+E8+E9+E10+E11+E12 | F13: =F4+F5+F6+F7+F8+F9+F10+F11+F12 | G13: =G4+G5+G6+G7+G8+G9+G10+G11+G12 | H13: =H4+H5+H6+H7+H8+H9+H10+H11+H12 | I13: =I4+I5+I6+I7+I8+I9+I10+I11+I12 | ... M13: =M4+M5+M6+M7+M8+M9+M10+M11+M12
A14: 2. PLURIEMPLEO (Otros empleos)
A15: Retribuciones Habituales Pluriempleo | B15: 0 | C15: 0 | D15: 0 | E15: 0 | F15: 0 | G15: 0 | H15: 0 | I15: 0 | J15: 0 | K15: 0 | L15: 0 | M15: 0
A16: Retribuciones No Habituales Pluriempleo | B16: 0 | C16: 0 | D16: 0 | E16: 0 | F16: 0 | G16: 0 | H16: 0 | I16: 0 | J16: 0 | K16: 0 | L16: 0 | M16: 0
A17: SAC Pluriempleo | B17: 0 | C17: 0 | D17: 0 | E17: 0 | F17: 0 | G17: 0 | H17: 0 | I17: 0 | J17: 0 | K17: 0 | L17: 0 | M17: 0
A18: Total Pluriempleo | B18: =B15+B16+B17 | C18: =C15+C16+C17 | D18: =D15+D16+D17 | E18: =E15+E16+E17 | F18: =F15+F16+F17 | G18: =G15+G16+G17 | H18: =H15+H16+H17 | I18: =I15+I16+I17 | ... M18: =M15+M16+M17
A19: 3. DESCUENTOS OBLIGATORIOS
A20: Base para Descuentos (con tope MoPre) | B20: =MIN(B4+B5+B6+B7+B8+B9+B12+B15+B17,2910574) | C20: =MIN(C4+C5+C6+C7+C8+C9+C12+C15+C17,2910574) | D20: =MIN(D4+D5+D6+D7+D8+D9+D12+D15+D17,2910574) | E20: =MIN(E4+E5+E6+E7+E8+E9+E12+E15+E17,2910574) | F20: =MIN(F4+F5+F6+F7+F8+F9+F12+F15+F17,2910574) | G20: =MIN(G4+G5+G6+G7+G8+G9+G12+G15+G17,2910574) | H20: =MIN(H4+H5+H6+H7+H8+H9+H12+H15+H17,2910574) | I20: =MIN(I4+I5+I6+I7+I8+I9+I12+I15+I17,2910574) | ... L20: =MIN(L4+L5+L6+L7+L8+L9+L12+L15+L17,2910574) | M20: =MIN(M4+M5+M6+M7+M8+M9+M12+M15+M17,3731212)
A21: Jubilación 11% | B21: =B20*0.11 | C21: =C20*0.11 | D21: =D20*0.11 | E21: =E20*0.11 | F21: =F20*0.11 | G21: =G20*0.11 | H21: =H20*0.11 | I21: =I20*0.11 | ... M21: =M20*0.11
A22: Obra Social 3% | B22: =B20*0.03 | C22: =C20*0.03 | D22: =D20*0.03 | E22: =E20*0.03 | F22: =F20*0.03 | G22: =G20*0.03 | H22: =H20*0.03 | I22: =I20*0.03 | ... M22: =M20*0.03
A23: INSSJP - Ley 19.032 3% | B23: =B20*0.03 | C23: =C20*0.03 | D23: =D20*0.03 | E23: =E20*0.03 | F23: =F20*0.03 | G23: =G20*0.03 | H23: =H20*0.03 | I23: =I20*0.03 | ... M23: =M20*0.03
A24: Aportes Sindicales | B24: 0 | C24: 0 | D24: 0 | E24: 0 | F24: 0 | G24: 0 | H24: 0 | I24: 0 | J24: 0 | K24: 0 | L24: 0 | M24: 0
A25: Otros Descuentos Obligatorios por Ley | B25: 0 | C25: 0 | D25: 0 | E25: 0 | F25: 0 | G25: 0 | H25: 0 | I25: 0 | J25: 0 | K25: 0 | L25: 0 | M25: 0
A26: Total Descuentos | B26: =SUM(B20:B25) | C26: =SUM(C20:C25) | D26: =SUM(D20:D25) | E26: =SUM(E20:E25) | F26: =SUM(F20:F25) | G26: =SUM(G20:G25) | H26: =SUM(H20:H25) | I26: =SUM(I20:I25) | ... M26: =SUM(M20:M25)
A27: 4. GANANCIA BRUTA
A28: Ganancia Bruta del Mes | B28: =B13+B18-B25 | C28: =C13+C18-C25 | D28: =D13+D18-D25 | E28: =E13+E18-E25 | F28: =F13+F18-F25 | G28: =G13+G18-G25 | H28: =H13+H18-H25 | I28: =I13+I18-I25 | ... M28: =M13+M18-M25
A29: SAC Proporcional (Acum/12) | B29: =B31/12 | C29: =C31/12 | D29: =D31/12 | E29: =E31/12 | F29: =F31/12 | G29: =G31/12 | H29: =H31/12 | I29: =I31/12 | ... M29: =M31/12
A30: Ajuste SAC Semestral (Jun/Dic) | B30: 0 | C30: 0 | D30: 0 | E30: 0 | F30: 0 | G30: =G12-G28*6 | H30: 0 | I30: 0 | J30: 0 | K30: 0 | L30: 0 | M30: =M12-M28*12
A31: Ganancia Bruta con SAC Proporcional | B31: =B27+B28+B29 | C31: =C27+C28+C29 | D31: =D27+D28+D29 | E31: =E27+E28+E29 | F31: =F27+F28+F29 | G31: =G27+G28+G29 | H31: =H27+H28+H29 | I31: =I27+I28+I29 | ... M31: =M27+M28+M29
A32: Ganancia Bruta Acumulada | B32: =B27 | C32: =B31+C27 | D32: =C31+D27 | E32: =D31+E27 | F32: =E31+F27 | G32: =F31+G27 | H32: =G31+H27 | I32: =H31+I27 | J32: =I31+J27 | ... M32: =L31+M27
A33: Promedio Remuneración Bruta (para DEA) | B33: =B27 | C33: =AVERAGE(B27:C27) | D33: =AVERAGE(B27:D27) | E33: =AVERAGE(B27:E27) | F33: =AVERAGE(B27:F27) | G33: =AVERAGE(B27:G27) | H33: =AVERAGE(B27:H27) | I33: =AVERAGE(B27:I27) | J33: =AVERAGE(B27:J27) | K33: =AVERAGE(B27:K27) | L33: =AVERAGE(B27:L27) | M33: =AVERAGE(B27:M27)
A34: 5. DEDUCCIONES GENERALES
A35: Alquiler pagado (monto total) | B35: 0 | C35: 0 | D35: 0 | E35: 0 | F35: 0 | G35: 0 | H35: 0 | I35: 0 | J35: 0 | K35: 0 | L35: 0 | M35: 0
A36: Alquiler 40% (hasta MNI) | B36: =MIN(B34*0.4,Parametros!$B$3) | C36: =MIN(C34*0.4,Parametros!$B$3) | D36: =MIN(D34*0.4,Parametros!$B$3) | E36: =MIN(E34*0.4,Parametros!$B$3) | F36: =MIN(F34*0.4,Parametros!$B$3) | G36: =MIN(G34*0.4,Parametros!$B$3) | H36: =MIN(H34*0.4,Parametros!$E$3) | I36: =MIN(I34*0.4,Parametros!$E$3) | J36: =MIN(J34*0.4,Parametros!$E$3) | K36: =MIN(K34*0.4,Parametros!$E$3) | L36: =MIN(L34*0.4,Parametros!$E$3) | M36: =MIN(M34*0.4,Parametros!$E$3)
A37: Alquiler 10% Ley 27.737 | B37: =B34*0.1 | C37: =C34*0.1 | D37: =D34*0.1 | E37: =E34*0.1 | F37: =F34*0.1 | G37: =G34*0.1 | H37: =H34*0.1 | I37: =I34*0.1 | ... M37: =M34*0.1
A38: Medicina Prepaga (monto pagado) | B38: 0 | C38: 0 | D38: 0 | E38: 0 | F38: 0 | G38: 0 | H38: 0 | I38: 0 | J38: 0 | K38: 0 | L38: 0 | M38: 0
A39: Medicina Prepaga (deducible 5% GNSI) | B39: =MIN(B37,B31*0.05) | C39: =MIN(C37,C31*0.05) | D39: =MIN(D37,D31*0.05) | E39: =MIN(E37,E31*0.05) | F39: =MIN(F37,F31*0.05) | G39: =MIN(G37,G31*0.05) | H39: =MIN(H37,H31*0.05) | I39: =MIN(I37,I31*0.05) | ... M39: =MIN(M37,M31*0.05)
A40: Gastos de Educación (pagados) | B40: 0 | C40: 0 | D40: 0 | E40: 0 | F40: 0 | G40: 0 | H40: 0 | I40: 0 | J40: 0 | K40: 0 | L40: 0 | M40: 0
...

Sheet Instrucciones
A1: 📊 CALCULADORA DE RETENCIONES DE GANANCIAS 2025 - GUÍA DE USO COMPLETA
A3: 🎯 INTRODUCCIÓN
A4: Esta calculadora implementa el 100% del esquema de retenciones del Impuesto a las Ganancias 2025 según normativa ARCA (ex-AFIP), incluyendo:
A5: • Escalas progresivas actualizadas (Art. 94) para Enero-Junio 2025 y Julio-Diciembre 2025
A6: • Cálculo de SAC Proporcional mensual y Ajuste SAC Semestral (junio/diciembre)
A7: • Deducciones generales: Jubilación 11%, Obra Social 3%, INSSJP 3%, Aportes Sindicales
A8: • Deducciones especiales: Alquiler 40% + 10% (Ley 27.737), Medicina Prepaga 5%, Educación, Seguro de Vida, Donaciones, etc.
A9: • Deducciones personales: Ganancia No Imponible, Cónyuge, Hijos, Deducción Especial + Incremento 22% (Ley 27.743)
A10: • Pluriempleo (múltiples empleadores simultáneos)
A11: • Pagos a Cuenta (Apartado G)
A12: • Retenciones Reintegradas (Apartado H)
A13: • Tope de retención del 35% sobre sueldo neto
... A248: ════════════════════════════════════════════════════════════════════════════════

Sheet Resumen cálculo
B5: DETERMINACIÓN DEL IMPORTE A RETENER
B7: 1. Ganancia bruta del mes que se liquida (Apartado A) $ ........
B9: 2. Retribuciones no habituales de dicho mes (Apartado B) $ ........
B11: 3. Ganancia Sueldo Anual Complementario (Apartado C) $ ........
B13: 4. Deducciones a computar (Apartado D) $ (........)
B15: 5. Deducción Sueldo Anual Complementario (Apartado C) $ (........)
B17: 6. Ganancia neta del mes que se liquida $ =====
B19: 7. Ganancia neta de meses anteriores (dentro del mismo período fiscal) $ ........
B21: 8. Ganancia neta acumulada al mes que se liquida $ =====
B23: 9. Deducciones personales acumuladas al mes que se liquida (Apartado E):
B25: Ganancias no imponibles $ (........)
B27: Cargas de familia $ (........)
... B43: 15. Importe a retener/reintegrar en dicho mes $ =====
